<?xml version="1.0" ?>
<robot name="sanga" xmlns:xacro="http://www.ros.org/wiki/xacro">

<xacro:include filename="$(find sanga_description)/urdf/materials.xacro" />
<xacro:include filename="$(find sanga_description)/urdf/sanga.trans" />
<xacro:include filename="$(find sanga_description)/urdf/sanga.gazebo" />
<link name="base_link">
  <inertial>
    <origin xyz="0.142623683383175 0.0006808095018713983 0.05756489096288754" rpy="0 0 0"/>
    <mass value="1.2619925701305132"/>
    <inertia ixx="0.00125" iyy="0.00496" izz="0.005482" ixy="-4.6e-05" iyz="1.5e-05" ixz="0.000408"/>
  </inertial>
  <visual>
    <origin xyz="0 0 0" rpy="0 0 0"/>
    <geometry>
      <mesh filename="package://sanga_description/meshes/base_link.stl" scale="0.001 0.001 0.001"/>
    </geometry>
    <material name="silver"/>
  </visual>
  <collision>
    <origin xyz="0 0 0" rpy="0 0 0"/>
    <geometry>
      <mesh filename="package://sanga_description/meshes/base_link.stl" scale="0.001 0.001 0.001"/>
    </geometry>
  </collision>
</link>

<link name="wheel_2_1">
  <inertial>
    <origin xyz="-1.575842946410777e-07 -0.002500000000004457 -2.151884213180688e-08" rpy="0 0 0"/>
    <mass value="0.3082687791334984"/>
    <inertia ixx="0.000193" iyy="0.000385" izz="0.000193" ixy="-0.0" iyz="0.0" ixz="0.0"/>
  </inertial>
  <visual>
    <origin xyz="-0.053859 0.06 -0.049562" rpy="0 0 0"/>
    <geometry>
      <mesh filename="package://sanga_description/meshes/wheel_2_1.stl" scale="0.001 0.001 0.001"/>
    </geometry>
    <material name="silver"/>
  </visual>
  <collision>
    <origin xyz="-0.053859 0.06 -0.049562" rpy="0 0 0"/>
    <geometry>
      <mesh filename="package://sanga_description/meshes/wheel_2_1.stl" scale="0.001 0.001 0.001"/>
    </geometry>
  </collision>
</link>

<link name="wheel_1_1">
  <inertial>
    <origin xyz="-2.126832401166956e-07 0.00250000000000436 2.9007682911946775e-07" rpy="0 0 0"/>
    <mass value="0.3082687791334984"/>
    <inertia ixx="0.000193" iyy="0.000385" izz="0.000193" ixy="-0.0" iyz="0.0" ixz="0.0"/>
  </inertial>
  <visual>
    <origin xyz="-0.0548 -0.06 -0.050397" rpy="0 0 0"/>
    <geometry>
      <mesh filename="package://sanga_description/meshes/wheel_1_1.stl" scale="0.001 0.001 0.001"/>
    </geometry>
    <material name="silver"/>
  </visual>
  <collision>
    <origin xyz="-0.0548 -0.06 -0.050397" rpy="0 0 0"/>
    <geometry>
      <mesh filename="package://sanga_description/meshes/wheel_1_1.stl" scale="0.001 0.001 0.001"/>
    </geometry>
  </collision>
</link>

<link name="revert_1">
  <inertial>
    <origin xyz="-4.297910929373927e-07 1.2960771328396348e-07 0.003499895323311533" rpy="0 0 0"/>
    <mass value="0.019032514423702223"/>
    <inertia ixx="1e-06" iyy="1e-06" izz="1e-06" ixy="-0.0" iyz="0.0" ixz="0.0"/>
  </inertial>
  <visual>
    <origin xyz="-0.194976 -0.001512 -0.07899" rpy="0 0 0"/>
    <geometry>
      <mesh filename="package://sanga_description/meshes/revert_1.stl" scale="0.001 0.001 0.001"/>
    </geometry>
    <material name="silver"/>
  </visual>
  <collision>
    <origin xyz="-0.194976 -0.001512 -0.07899" rpy="0 0 0"/>
    <geometry>
      <mesh filename="package://sanga_description/meshes/revert_1.stl" scale="0.001 0.001 0.001"/>
    </geometry>
  </collision>
</link>

<joint name="Rev1" type="continuous">
  <origin xyz="0.053859 -0.06 0.049562" rpy="0 0 0"/>
  <parent link="base_link"/>
  <child link="rev 1"/>
  <axis xyz="0.0 1.0 0.0"/>
</joint>

<joint name="Rev2" type="continuous">
  <origin xyz="0.0548 0.06 0.050397" rpy="0 0 0"/>
  <parent link="base_link"/>
  <child link="rev 2"/>
  <axis xyz="0.0 1.0 0.0"/>
</joint>

<joint name="Rev3" type="continuous">
  <origin xyz="0.194976 0.001512 0.07899" rpy="0 0 0"/>
  <parent link="base_link"/>
  <child link="revert_1"/>
  <axis xyz="0.0 0.0 1.0"/>
</joint>

</robot>
